Workbook

Sheet Home
B2: Registration & Incident Selector
B3: Pick a Country and a System below — the table auto-updates via formula lookups.
B5: Country: | C5: USA
B6: System: | C6: Trellis Forearm System
B8: Matching catalog items for the selected System:
B9: Catalog # | C9: Description | D9: Registration Name | E9: Registration # | F9: Approval Date | G9: Expiration Date
B10: =IFERROR(INDEX('Master Catalog'!$B$2:$B$41,MATCH($C$6&"|"&1,'Master Catalog'!$L$2:$L$41,0)),"") -> TRL-110-1 | C10: =IFERROR(INDEX('Master Catalog'!$C$2:$C$41,MATCH($B10,'Master Catalog'!$B$2:$B$41,0)),"") -> Screw, 2.4mm x 24mm, Trellis family | D10: =IFERROR(INDEX('Country Registrations'!$E$2:$E$201,MATCH($C$5&"|"&$B10,'Country Registrations'!$I$2:$I$201,0)),"") -> Trellis Forearm System - USA Registration | E10: =IFERROR(INDEX('Country Registrations'!$F$2:$F$201,MATCH($C$5&"|"&$B10,'Country Registrations'!$I$2:$I$201,0)),"") -> K109444 | F10: =IFERROR(INDEX('Country Registrations'!$G$2:$G$201,MATCH($C$5&"|"&$B10,'Country Registrations'!$I$2:$I$201,0)),"") -> 05/01/2019 | G10: =IFERROR(INDEX('Country Registrations'!$H$2:$H$201,MATCH($C$5&"|"&$B10,'Country Registrations'!$I$2:$I$201,0)),"") -> N/A
B11: =IFERROR(INDEX('Master Catalog'!$B$2:$B$41,MATCH($C$6&"|"&2,'Master Catalog'!$L$2:$L$41,0)),"") -> TRL-120-2 | C11: =IFERROR(INDEX('Master Catalog'!$C$2:$C$41,MATCH($B11,'Master Catalog'!$B$2:$B$41,0)),"") -> Instrument, 2.4mm x 10mm, Trellis family | D11: =IFERROR(INDEX('Country Registrations'!$E$2:$E$201,MATCH($C$5&"|"&$B11,'Country Registrations'!$I$2:$I$201,0)),"") -> Trellis Forearm System - USA Registration | E11: =IFERROR(INDEX('Country Registrations'!$F$2:$F$201,MATCH($C$5&"|"&$B11,'Country Registrations'!$I$2:$I$201,0)),"") -> K158309 | F11: =IFERROR(INDEX('Country Registrations'!$G$2:$G$201,MATCH($C$5&"|"&$B11,'Country Registrations'!$I$2:$I$201,0)),"") -> 10/04/2017 | G11: =IFERROR(INDEX('Country Registrations'!$H$2:$H$201,MATCH($C$5&"|"&$B11,'Country Registrations'!$I$2:$I$201,0)),"") -> N/A
B12: =IFERROR(INDEX('Master Catalog'!$B$2:$B$41,MATCH($C$6&"|"&3,'Master Catalog'!$L$2:$L$41,0)),"") -> TRL-130-3 | C12: =IFERROR(INDEX('Master Catalog'!$C$2:$C$41,MATCH($B12,'Master Catalog'!$B$2:$B$41,0)),"") -> Plate, 4.0mm x 20mm, Trellis family | D12: =IFERROR(INDEX('Country Registrations'!$E$2:$E$201,MATCH($C$5&"|"&$B12,'Country Registrations'!$I$2:$I$201,0)),"") -> Trellis Forearm System - USA Registration | E12: =IFERROR(INDEX('Country Registrations'!$F$2:$F$201,MATCH($C$5&"|"&$B12,'Country Registrations'!$I$2:$I$201,0)),"") -> K214309 | F12: =IFERROR(INDEX('Country Registrations'!$G$2:$G$201,MATCH($C$5&"|"&$B12,'Country Registrations'!$I$2:$I$201,0)),"") -> 14/02/2014 | G12: =IFERROR(INDEX('Country Registrations'!$H$2:$H$201,MATCH($C$5&"|"&$B12,'Country Registrations'!$I$2:$I$201,0)),"") -> N/A
B13: =IFERROR(INDEX('Master Catalog'!$B$2:$B$41,MATCH($C$6&"|"&4,'Master Catalog'!$L$2:$L$41,0)),"") -> TRL-140-4 | C13: =IFERROR(INDEX('Master Catalog'!$C$2:$C$41,MATCH($B13,'Master Catalog'!$B$2:$B$41,0)),"") -> Plate, 2.7mm x 14mm, Trellis family | D13: =IFERROR(INDEX('Country Registrations'!$E$2:$E$201,MATCH($C$5&"|"&$B13,'Country Registrations'!$I$2:$I$201,0)),"") -> Trellis Forearm System - USA Registration | E13: =IFERROR(INDEX('Country Registrations'!$F$2:$F$201,MATCH($C$5&"|"&$B13,'Country Registrations'!$I$2:$I$201,0)),"") -> K184475 | F13: =IFERROR(INDEX('Country Registrations'!$G$2:$G$201,MATCH($C$5&"|"&$B13,'Country Registrations'!$I$2:$I$201,0)),"") -> 22/04/2021 | G13: =IFERROR(INDEX('Country Registrations'!$H$2:$H$201,MATCH($C$5&"|"&$B13,'Country Registrations'!$I$2:$I$201,0)),"") -> N/A
B14: =IFERROR(INDEX('Master Catalog'!$B$2:$B$41,MATCH($C$6&"|"&5,'Master Catalog'!$L$2:$L$41,0)),"") -> TRL-150-5 | C14: =IFERROR(INDEX('Master Catalog'!$C$2:$C$41,MATCH($B14,'Master Catalog'!$B$2:$B$41,0)),"") -> Other, 2.4mm x 24mm, Trellis family | D14: =IFERROR(INDEX('Country Registrations'!$E$2:$E$201,MATCH($C$5&"|"&$B14,'Country Registrations'!$I$2:$I$201,0)),"") -> Trellis Forearm System - USA Registration | E14: =IFERROR(INDEX('Country Registrations'!$F$2:$F$201,MATCH($C$5&"|"&$B14,'Country Registrations'!$I$2:$I$201,0)),"") -> K101453 | F14: =IFERROR(INDEX('Country Registrations'!$G$2:$G$201,MATCH($C$5&"|"&$B14,'Country Registrations'!$I$2:$I$201,0)),"") -> 06/12/2015 | G14: =IFERROR(INDEX('Country Registrations'!$H$2:$H$201,MATCH($C$5&"|"&$B14,'Country Registrations'!$I$2:$I$201,0)),"") -> N/A
B15: =IFERROR(INDEX('Master Catalog'!$B$2:$B$41,MATCH($C$6&"|"&6,'Master Catalog'!$L$2:$L$41,0)),"") -> TRL-160-6 | C15: =IFERROR(INDEX('Master Catalog'!$C$2:$C$41,MATCH($B15,'Master Catalog'!$B$2:$B$41,0)),"") -> Other, 4.5mm x 12mm, Trellis family | D15: =IFERROR(INDEX('Country Registrations'!$E$2:$E$201,MATCH($C$5&"|"&$B15,'Country Registrations'!$I$2:$I$201,0)),"") -> Trellis Forearm System - USA Registration | E15: =IFERROR(INDEX('Country Registrations'!$F$2:$F$201,MATCH($C$5&"|"&$B15,'Country Registrations'!$I$2:$I$201,0)),"") -> K174901 | F15: =IFERROR(INDEX('Country Registrations'!$G$2:$G$201,MATCH($C$5&"|"&$B15,'Country Registrations'!$I$2:$I$201,0)),"") -> 11/09/2017 | G15: =IFERROR(INDEX('Country Registrations'!$H$2:$H$201,MATCH($C$5&"|"&$B15,'Country Registrations'!$I$2:$I$201,0)),"") -> N/A
B16: =IFERROR(INDEX('Master Catalog'!$B$2:$B$41,MATCH($C$6&"|"&7,'Master Catalog'!$L$2:$L$41,0)),"") -> TRL-170-7 | C16: =IFERROR(INDEX('Master Catalog'!$C$2:$C$41,MATCH($B16,'Master Catalog'!$B$2:$B$41,0)),"") -> Plate, 2.4mm x 16mm, Trellis family | D16: =IFERROR(INDEX('Country Registrations'!$E$2:$E$201,MATCH($C$5&"|"&$B16,'Country Registrations'!$I$2:$I$201,0)),"") -> Trellis Forearm System - USA Registration | E16: =IFERROR(INDEX('Country Registrations'!$F$2:$F$201,MATCH($C$5&"|"&$B16,'Country Registrations'!$I$2:$I$201,0)),"") -> K157812 | F16: =IFERROR(INDEX('Country Registrations'!$G$2:$G$201,MATCH($C$5&"|"&$B16,'Country Registrations'!$I$2:$I$201,0)),"") -> 14/08/2021 | G16: =IFERROR(INDEX('Country Registrations'!$H$2:$H$201,MATCH($C$5&"|"&$B16,'Country Registrations'!$I$2:$I$201,0)),"") -> N/A
B17: =IFERROR(INDEX('Master Catalog'!$B$2:$B$41,MATCH($C$6&"|"&8,'Master Catalog'!$L$2:$L$41,0)),"") -> TRL-180-8 | C17: =IFERROR(INDEX('Master Catalog'!$C$2:$C$41,MATCH($B17,'Master Catalog'!$B$2:$B$41,0)),"") -> Plate, 3.5mm x 24mm, Trellis family | D17: =IFERROR(INDEX('Country Registrations'!$E$2:$E$201,MATCH($C$5&"|"&$B17,'Country Registrations'!$I$2:$I$201,0)),"") -> Trellis Forearm System - USA Registration | E17: =IFERROR(INDEX('Country Registrations'!$F$2:$F$201,MATCH($C$5&"|"&$B17,'Country Registrations'!$I$2:$I$201,0)),"") -> K166131 | F17: =IFERROR(INDEX('Country Registrations'!$G$2:$G$201,MATCH($C$5&"|"&$B17,'Country Registrations'!$I$2:$I$201,0)),"") -> 24/09/2015 | G17: =IFERROR(INDEX('Country Registrations'!$H$2:$H$201,MATCH($C$5&"|"&$B17,'Country Registrations'!$I$2:$I$201,0)),"") -> N/A
B19: Open incidents (Under Investigation) for selected System: | E19: =COUNTIFS('Master RIL'!$C$2:$C$142,$C$6,'Master RIL'!$H$2:$H$142,"Under Investigation") -> 12

Sheet Read Me
B2: Mental Schematics — Multi-Country / Multi-System Registration & Incident Tracker
B3: Sample company — Mental Schematics is not a real business.
B4: All countries, systems, part numbers, registrations, and incidents below are fictional.
B7: What this workbook demonstrates:
B8: • A single maintained workbook standing in for what would otherwise be a spreadsheet
B9: per country/system combination (here: 5 countries x 5 systems = 25 combinations).
B10: • A Home sheet where you pick a Country and a System from dropdowns, and the relevant
B11: catalog, registration, and incident data is pulled in automatically via formulas.
B12: • A consistent maintenance procedure for adding a new country or a new system without
B13: restructuring existing sheets (see 'Maintenance Procedure' tab).
B15: Sheets:
B16: Home - country/system selector + auto-populated summary
... B24: pop-up country/system selector, for use in Excel desktop

Sheet Master Catalog
A1: Item Category | B1: Catalog # | C1: Description | D1: UDI Number | E1: Part Drawing # | F1: IFU # | G1: Material | H1: Sterile? | I1: Active? | J1: System | K1: System Seq | L1: Key (System|Seq)
A2: Implant Screw | B2: TRL-110-1 | C2: Screw, 2.4mm x 24mm, Trellis family | D2: 008395310485 | E2: DRW-42098-01 | F2: IFU-4657-00 | G2: CoCr Alloy | H2: Y | I2: Y | J2: Trellis Forearm System | K2: 1 | L2: =J2&"|"&K2 -> Trellis Forearm System|1
A3: Instrument | B3: TRL-120-2 | C3: Instrument, 2.4mm x 10mm, Trellis family | D3: 008200604502 | E3: DRW-38657-02 | F3: IFU-4811-00 | G3: Ti 6Al-4V ELI | H3: Y | I3: N | J3: Trellis Forearm System | K3: 2 | L3: =J3&"|"&K3 -> Trellis Forearm System|2
A4: Implant Plate | B4: TRL-130-3 | C4: Plate, 4.0mm x 20mm, Trellis family | D4: 008398704996 | E4: DRW-10851-03 | F4: IFU-3615-00 | G4: PEEK | H4: N | I4: Y | J4: Trellis Forearm System | K4: 3 | L4: =J4&"|"&K4 -> Trellis Forearm System|3
A5: Implant Plate | B5: TRL-140-4 | C5: Plate, 2.7mm x 14mm, Trellis family | D5: 008209747451 | E5: DRW-22156-04 | F5: IFU-7224-00 | G5: Ti 6Al-4V ELI | H5: N | I5: Y | J5: Trellis Forearm System | K5: 4 | L5: =J5&"|"&K5 -> Trellis Forearm System|4
A6: Implant Other | B6: TRL-150-5 | C6: Other, 2.4mm x 24mm, Trellis family | D6: 008593303705 | E6: DRW-80284-05 | F6: IFU-3045-00 | G6: PEEK | H6: Y | I6: Y | J6: Trellis Forearm System | K6: 5 | L6: =J6&"|"&K6 -> Trellis Forearm System|5
A7: Implant Other | B7: TRL-160-6 | C7: Other, 4.5mm x 12mm, Trellis family | D7: 008856528252 | E7: DRW-19116-06 | F7: IFU-1750-00 | G7: CoCr Alloy | H7: N | I7: Y | J7: Trellis Forearm System | K7: 6 | L7: =J7&"|"&K7 -> Trellis Forearm System|6
A8: Implant Plate | B8: TRL-170-7 | C8: Plate, 2.4mm x 16mm, Trellis family | D8: 008398471886 | E8: DRW-69429-07 | F8: IFU-6977-00 | G8: CoCr Alloy | H8: N | I8: Y | J8: Trellis Forearm System | K8: 7 | L8: =J8&"|"&K8 -> Trellis Forearm System|7
A9: Implant Plate | B9: TRL-180-8 | C9: Plate, 3.5mm x 24mm, Trellis family | D9: 008833953718 | E9: DRW-94939-08 | F9: IFU-2169-00 | G9: CoCr Alloy | H9: Y | I9: Y | J9: Trellis Forearm System | K9: 8 | L9: =J9&"|"&K9 -> Trellis Forearm System|8
A10: Instrument | B10: VLX-110-1 | C10: Instrument, 4.0mm x 14mm, Voltix family | D10: 008787194506 | E10: DRW-83000-01 | F10: IFU-4598-00 | G10: 316L Stainless | H10: Y | I10: Y | J10: Voltix Plating System | K10: 1 | L10: =J10&"|"&K10 -> Voltix Plating System|1
A11: Implant Screw | B11: VLX-120-2 | C11: Screw, 3.5mm x 16mm, Voltix family | D11: 008387484583 | E11: DRW-18675-02 | F11: IFU-4456-00 | G11: 316L Stainless | H11: Y | I11: N | J11: Voltix Plating System | K11: 2 | L11: =J11&"|"&K11 -> Voltix Plating System|2
A12: Instrument | B12: VLX-130-3 | C12: Instrument, 4.0mm x 12mm, Voltix family | D12: 008384412919 | E12: DRW-28301-03 | F12: IFU-5040-00 | G12: 316L Stainless | H12: N | I12: N | J12: Voltix Plating System | K12: 3 | L12: =J12&"|"&K12 -> Voltix Plating System|3
A13: Implant Other | B13: VLX-140-4 | C13: Other, 2.7mm x 12mm, Voltix family | D13: 008647099690 | E13: DRW-74686-04 | F13: IFU-2489-00 | G13: Ti 6Al-4V ELI | H13: Y | I13: Y | J13: Voltix Plating System | K13: 4 | L13: =J13&"|"&K13 -> Voltix Plating System|4
... A41: Instrument | B41: CVD-180-8 | C41: Instrument, 4.5mm x 24mm, Corvid family | D41: 008559225330 | E41: DRW-83519-08 | F41: IFU-1158-00 | G41: Ti 6Al-4V ELI | H41: Y | I41: Y | J41: Corvid Fragment System | K41: 8 | L41: =J41&"|"&K41 -> Corvid Fragment System|8

Sheet PBS
A1: Catalog # | B1: Trellis Forearm System | C1: Voltix Plating System | D1: Anchorix Suture System | E1: Radiant Nail System | F1: Corvid Fragment System
A2: TRL-110-1 | B2: ✔
A3: TRL-120-2 | B3: ✔
A4: TRL-130-3 | B4: ✔
A5: TRL-140-4 | B5: ✔
A6: TRL-150-5 | B6: ✔
A7: TRL-160-6 | B7: ✔
A8: TRL-170-7 | B8: ✔
A9: TRL-180-8 | B9: ✔
A10: VLX-110-1 | C10: ✔
A11: VLX-120-2 | C11: ✔
A12: VLX-130-3 | C12: ✔
A13: VLX-140-4 | C13: ✔
A14: VLX-150-5 | C14: ✔
A15: VLX-160-6 | C15: ✔
A16: VLX-170-7 | C16: ✔
A17: VLX-180-8 | C17: ✔
A18: ANX-110-1 | D18: ✔
A19: ANX-120-2 | D19: ✔
A20: ANX-130-3 | D20: ✔
A21: ANX-140-4 | D21: ✔
A22: ANX-150-5 | D22: ✔
A23: ANX-160-6 | D23: ✔
A24: ANX-170-7 | D24: ✔
A25: ANX-180-8 | D25: ✔
A26: RAD-110-1 | E26: ✔
A27: RAD-120-2 | E27: ✔
A28: RAD-130-3 | E28: ✔
A29: RAD-140-4 | E29: ✔
A30: RAD-150-5 | E30: ✔
A31: RAD-160-6 | E31: ✔
A32: RAD-170-7 | E32: ✔
A33: RAD-180-8 | E33: ✔
A34: CVD-110-1 | F34: ✔
A35: CVD-120-2 | F35: ✔
A36: CVD-130-3 | F36: ✔
A37: CVD-140-4 | F37: ✔
A38: CVD-150-5 | F38: ✔
A39: CVD-160-6 | F39: ✔
A40: CVD-170-7 | F40: ✔
...

Sheet Country Registrations
A1: Catalog # | B1: Country | C1: Country Class | D1: Country Rule | E1: Registration Name | F1: Registration Number | G1: Approval Date | H1: Expiration Date | I1: Key (Country|Catalog#)
A2: TRL-110-1 | B2: USA | C2: IIa | D2: 7 | E2: Trellis Forearm System - USA Registration | F2: K109444 | G2: 05/01/2019 | H2: N/A | I2: =B2&"|"&A2 -> USA|TRL-110-1
A3: TRL-110-1 | B3: Germany | C3: I | D3: 6 | E3: Trellis Forearm System - Germany Registration | F3: DE-CE-6050 | G3: 07/11/2019 | H3: 08/11/2024 | I3: =B3&"|"&A3 -> Germany|TRL-110-1
A4: TRL-110-1 | B4: Brazil | C4: III | D4: 3 | E4: Trellis Forearm System - Brazil Registration | F4: ANVISA-23473 | G4: 08/03/2019 | H4: 26/03/2024 | I4: =B4&"|"&A4 -> Brazil|TRL-110-1
A5: TRL-110-1 | B5: Japan | C5: IIa | D5: 6 | E5: Trellis Forearm System - Japan Registration | F5: PMDA-532322 | G5: 26/07/2014 | H5: 26/11/2019 | I5: =B5&"|"&A5 -> Japan|TRL-110-1
A6: TRL-110-1 | B6: Australia | C6: IIa | D6: 2 | E6: Trellis Forearm System - Australia Registration | F6: ARTG-230111 | G6: 13/01/2018 | H6: 28/08/2023 | I6: =B6&"|"&A6 -> Australia|TRL-110-1
A7: TRL-120-2 | B7: USA | C7: III | D7: 6 | E7: Trellis Forearm System - USA Registration | F7: K158309 | G7: 10/04/2017 | H7: N/A | I7: =B7&"|"&A7 -> USA|TRL-120-2
A8: TRL-120-2 | B8: Germany | C8: IIa | D8: 7 | E8: Trellis Forearm System - Germany Registration | F8: DE-CE-4652 | G8: 11/05/2014 | H8: 28/02/2019 | I8: =B8&"|"&A8 -> Germany|TRL-120-2
A9: TRL-120-2 | B9: Brazil | C9: III | D9: 6 | E9: Trellis Forearm System - Brazil Registration | F9: ANVISA-46585 | G9: 01/02/2019 | H9: 09/03/2024 | I9: =B9&"|"&A9 -> Brazil|TRL-120-2
A10: TRL-120-2 | B10: Japan | C10: I | D10: 2 | E10: Trellis Forearm System - Japan Registration | F10: PMDA-708792 | G10: 20/07/2018 | H10: 12/12/2023 | I10: =B10&"|"&A10 -> Japan|TRL-120-2
A11: TRL-120-2 | B11: Australia | C11: I | D11: 7 | E11: Trellis Forearm System - Australia Registration | F11: ARTG-264457 | G11: 19/04/2020 | H11: 09/01/2025 | I11: =B11&"|"&A11 -> Australia|TRL-120-2
A12: TRL-130-3 | B12: USA | C12: IIa | D12: 6 | E12: Trellis Forearm System - USA Registration | F12: K214309 | G12: 14/02/2014 | H12: N/A | I12: =B12&"|"&A12 -> USA|TRL-130-3
A13: TRL-130-3 | B13: Germany | C13: IIb | D13: 2 | E13: Trellis Forearm System - Germany Registration | F13: DE-CE-6409 | G13: 24/05/2023 | H13: 17/05/2028 | I13: =B13&"|"&A13 -> Germany|TRL-130-3
... A201: CVD-180-8 | B201: Australia | C201: I | D201: 6 | E201: Corvid Fragment System - Australia Registration | F201: ARTG-274024 | G201: 14/07/2018 | H201: 24/08/2023 | I201: =B201&"|"&A201 -> Australia|CVD-180-8

Sheet Master RIL
A1: Incident ID | B1: Catalog # | C1: System | D1: Date Reported | E1: Incident Type | F1: Severity | G1: Corrective Action | H1: Status
A2: INC-1001 | B2: TRL-110-1 | C2: Trellis Forearm System | D2: 06/08/2023 | E2: Sterility indicator failure | F2: Medium | G2: Root cause traced to packaging vendor, spec updated | H2: Under Investigation
A3: INC-1002 | B3: TRL-110-1 | C3: Trellis Forearm System | D3: 24/07/2021 | E3: Bent on delivery | F3: Medium | G3: CAPA opened, in-process inspection added | H3: Closed - CAPA Issued
A4: INC-1003 | B4: TRL-110-1 | C4: Trellis Forearm System | D4: 10/06/2025 | E4: Bent on delivery | F4: Low | G4: Root cause traced to packaging vendor, spec updated | H4: Under Investigation
A5: INC-1004 | B5: TRL-110-1 | C5: Trellis Forearm System | D5: 15/10/2023 | E5: Sterility indicator failure | F5: Medium | G5: Unit replaced under warranty, no trend identified | H5: Closed - Replaced Unit
A6: INC-1005 | B6: TRL-110-1 | C6: Trellis Forearm System | D6: 15/01/2023 | E6: Sterility indicator failure | F6: Medium | G6: CAPA opened, in-process inspection added | H6: Closed - Replaced Unit
A7: INC-1006 | B7: TRL-120-2 | C7: Trellis Forearm System | D7: 26/01/2026 | E7: Bent on delivery | F7: High | G7: No corrective action required, isolated event | H7: Under Investigation
A8: INC-1007 | B8: TRL-120-2 | C8: Trellis Forearm System | D8: 26/12/2025 | E8: Sterility indicator failure | F8: Low | G8: Vendor notified, incoming inspection tightened | H8: Closed - CAPA Issued
A9: INC-1008 | B9: TRL-120-2 | C9: Trellis Forearm System | D9: 22/08/2025 | E9: Bent on delivery | F9: Low | G9: Vendor notified, incoming inspection tightened | H9: Closed - CAPA Issued
A10: INC-1009 | B10: TRL-120-2 | C10: Trellis Forearm System | D10: 12/06/2026 | E10: Surface finish nonconformance | F10: High | G10: Vendor notified, incoming inspection tightened | H10: Closed - CAPA Issued
A11: INC-1010 | B11: TRL-130-3 | C11: Trellis Forearm System | D11: 12/08/2023 | E11: Bent on delivery | F11: High | G11: Unit replaced under warranty, no trend identified | H11: Under Investigation
A12: INC-1011 | B12: TRL-130-3 | C12: Trellis Forearm System | D12: 11/11/2024 | E12: Labeling discrepancy | F12: Low | G12: Vendor notified, incoming inspection tightened | H12: Closed - No Action
... A142: INC-1141 | B142: CVD-180-8 | C142: Corvid Fragment System | D142: 12/02/2023 | E142: Bent on delivery | F142: Low | G142: Root cause traced to packaging vendor, spec updated | H142: Closed - Replaced Unit

Sheet RIL - Trellis
B1: Trellis Forearm System
A3: Incident ID | B3: Catalog # | C3: Date Reported | D3: Incident Type | E3: Severity | F3: Corrective Action | G3: Status
A4: INC-1001 | B4: TRL-110-1 | C4: 06/08/2023 | D4: Sterility indicator failure | E4: Medium | F4: Root cause traced to packaging vendor, spec updated | G4: Under Investigation
A5: INC-1002 | B5: TRL-110-1 | C5: 24/07/2021 | D5: Bent on delivery | E5: Medium | F5: CAPA opened, in-process inspection added | G5: Closed - CAPA Issued
A6: INC-1003 | B6: TRL-110-1 | C6: 10/06/2025 | D6: Bent on delivery | E6: Low | F6: Root cause traced to packaging vendor, spec updated | G6: Under Investigation
A7: INC-1004 | B7: TRL-110-1 | C7: 15/10/2023 | D7: Sterility indicator failure | E7: Medium | F7: Unit replaced under warranty, no trend identified | G7: Closed - Replaced Unit
A8: INC-1005 | B8: TRL-110-1 | C8: 15/01/2023 | D8: Sterility indicator failure | E8: Medium | F8: CAPA opened, in-process inspection added | G8: Closed - Replaced Unit
A9: INC-1006 | B9: TRL-120-2 | C9: 26/01/2026 | D9: Bent on delivery | E9: High | F9: No corrective action required, isolated event | G9: Under Investigation
A10: INC-1007 | B10: TRL-120-2 | C10: 26/12/2025 | D10: Sterility indicator failure | E10: Low | F10: Vendor notified, incoming inspection tightened | G10: Closed - CAPA Issued
A11: INC-1008 | B11: TRL-120-2 | C11: 22/08/2025 | D11: Bent on delivery | E11: Low | F11: Vendor notified, incoming inspection tightened | G11: Closed - CAPA Issued
A12: INC-1009 | B12: TRL-120-2 | C12: 12/06/2026 | D12: Surface finish nonconformance | E12: High | F12: Vendor notified, incoming inspection tightened | G12: Closed - CAPA Issued
A13: INC-1010 | B13: TRL-130-3 | C13: 12/08/2023 | D13: Bent on delivery | E13: High | F13: Unit replaced under warranty, no trend identified | G13: Under Investigation
A14: INC-1011 | B14: TRL-130-3 | C14: 11/11/2024 | D14: Labeling discrepancy | E14: Low | F14: Vendor notified, incoming inspection tightened | G14: Closed - No Action
... A33: INC-1030 | B33: TRL-180-8 | C33: 03/12/2024 | D33: Bent on delivery | E33: Low | F33: No corrective action required, isolated event | G33: Closed - Replaced Unit

Sheet RIL - Voltix
B1: Voltix Plating System
A3: Incident ID | B3: Catalog # | C3: Date Reported | D3: Incident Type | E3: Severity | F3: Corrective Action | G3: Status
A4: INC-1031 | B4: VLX-110-1 | C4: 07/06/2024 | D4: Dimensional out of spec | E4: Low | F4: Root cause traced to packaging vendor, spec updated | G4: Under Investigation
A5: INC-1032 | B5: VLX-110-1 | C5: 28/06/2026 | D5: Surface finish nonconformance | E5: Low | F5: Root cause traced to packaging vendor, spec updated | G5: Closed - No Action
A6: INC-1033 | B6: VLX-110-1 | C6: 08/08/2023 | D6: Bent on delivery | E6: Medium | F6: No corrective action required, isolated event | G6: Closed - CAPA Issued
A7: INC-1034 | B7: VLX-110-1 | C7: 04/01/2022 | D7: Labeling discrepancy | E7: Medium | F7: CAPA opened, in-process inspection added | G7: Closed - Replaced Unit
A8: INC-1035 | B8: VLX-110-1 | C8: 28/03/2022 | D8: Labeling discrepancy | E8: High | F8: Root cause traced to packaging vendor, spec updated | G8: Closed - CAPA Issued
A9: INC-1036 | B9: VLX-120-2 | C9: 17/08/2024 | D9: Surface finish nonconformance | E9: Medium | F9: No corrective action required, isolated event | G9: Closed - No Action
A10: INC-1037 | B10: VLX-120-2 | C10: 13/09/2021 | D10: Surface finish nonconformance | E10: Low | F10: Unit replaced under warranty, no trend identified | G10: Under Investigation
A11: INC-1038 | B11: VLX-120-2 | C11: 02/05/2021 | D11: Surface finish nonconformance | E11: High | F11: No corrective action required, isolated event | G11: Under Investigation
A12: INC-1039 | B12: VLX-130-3 | C12: 14/03/2021 | D12: Labeling discrepancy | E12: High | F12: Root cause traced to packaging vendor, spec updated | G12: Closed - Replaced Unit
A13: INC-1040 | B13: VLX-130-3 | C13: 02/07/2023 | D13: Bent on delivery | E13: High | F13: CAPA opened, in-process inspection added | G13: Closed - CAPA Issued
A14: INC-1041 | B14: VLX-140-4 | C14: 10/02/2025 | D14: Surface finish nonconformance | E14: High | F14: No corrective action required, isolated event | G14: Under Investigation
... A30: INC-1057 | B30: VLX-180-8 | C30: 16/04/2025 | D30: Packaging breach | E30: Medium | F30: CAPA opened, in-process inspection added | G30: Under Investigation

Sheet RIL - Anchorix
B1: Anchorix Suture System
A3: Incident ID | B3: Catalog # | C3: Date Reported | D3: Incident Type | E3: Severity | F3: Corrective Action | G3: Status
A4: INC-1058 | B4: ANX-110-1 | C4: 25/05/2023 | D4: Sterility indicator failure | E4: Low | F4: No corrective action required, isolated event | G4: Under Investigation
A5: INC-1059 | B5: ANX-110-1 | C5: 12/09/2024 | D5: Sterility indicator failure | E5: Medium | F5: Root cause traced to packaging vendor, spec updated | G5: Closed - No Action
A6: INC-1060 | B6: ANX-110-1 | C6: 22/09/2025 | D6: Surface finish nonconformance | E6: Medium | F6: Root cause traced to packaging vendor, spec updated | G6: Closed - CAPA Issued
A7: INC-1061 | B7: ANX-120-2 | C7: 10/12/2021 | D7: Bent on delivery | E7: Medium | F7: No corrective action required, isolated event | G7: Under Investigation
A8: INC-1062 | B8: ANX-120-2 | C8: 16/04/2026 | D8: Packaging breach | E8: High | F8: Root cause traced to packaging vendor, spec updated | G8: Under Investigation
A9: INC-1063 | B9: ANX-120-2 | C9: 04/10/2022 | D9: Sterility indicator failure | E9: High | F9: Unit replaced under warranty, no trend identified | G9: Closed - CAPA Issued
A10: INC-1064 | B10: ANX-120-2 | C10: 22/09/2021 | D10: Packaging breach | E10: High | F10: Unit replaced under warranty, no trend identified | G10: Closed - No Action
A11: INC-1065 | B11: ANX-130-3 | C11: 11/12/2024 | D11: Surface finish nonconformance | E11: Low | F11: Unit replaced under warranty, no trend identified | G11: Closed - No Action
A12: INC-1066 | B12: ANX-130-3 | C12: 06/07/2025 | D12: Sterility indicator failure | E12: Medium | F12: No corrective action required, isolated event | G12: Closed - CAPA Issued
A13: INC-1067 | B13: ANX-140-4 | C13: 10/11/2023 | D13: Bent on delivery | E13: Low | F13: CAPA opened, in-process inspection added | G13: Closed - CAPA Issued
A14: INC-1068 | B14: ANX-140-4 | C14: 24/12/2025 | D14: Bent on delivery | E14: Low | F14: No corrective action required, isolated event | G14: Closed - CAPA Issued
... A31: INC-1085 | B31: ANX-180-8 | C31: 28/09/2023 | D31: Surface finish nonconformance | E31: Low | F31: Unit replaced under warranty, no trend identified | G31: Closed - Replaced Unit

Sheet RIL - Radiant
B1: Radiant Nail System
A3: Incident ID | B3: Catalog # | C3: Date Reported | D3: Incident Type | E3: Severity | F3: Corrective Action | G3: Status
A4: INC-1086 | B4: RAD-110-1 | C4: 15/01/2025 | D4: Surface finish nonconformance | E4: Low | F4: CAPA opened, in-process inspection added | G4: Closed - Replaced Unit
A5: INC-1087 | B5: RAD-110-1 | C5: 19/01/2024 | D5: Dimensional out of spec | E5: Medium | F5: Root cause traced to packaging vendor, spec updated | G5: Closed - No Action
A6: INC-1088 | B6: RAD-120-2 | C6: 27/01/2023 | D6: Sterility indicator failure | E6: Low | F6: CAPA opened, in-process inspection added | G6: Closed - No Action
A7: INC-1089 | B7: RAD-120-2 | C7: 14/06/2021 | D7: Sterility indicator failure | E7: Low | F7: CAPA opened, in-process inspection added | G7: Closed - No Action
A8: INC-1090 | B8: RAD-120-2 | C8: 16/01/2021 | D8: Labeling discrepancy | E8: Medium | F8: Unit replaced under warranty, no trend identified | G8: Closed - CAPA Issued
A9: INC-1091 | B9: RAD-120-2 | C9: 24/11/2026 | D9: Surface finish nonconformance | E9: Medium | F9: No corrective action required, isolated event | G9: Closed - Replaced Unit
A10: INC-1092 | B10: RAD-120-2 | C10: 13/02/2024 | D10: Sterility indicator failure | E10: High | F10: CAPA opened, in-process inspection added | G10: Closed - CAPA Issued
A11: INC-1093 | B11: RAD-130-3 | C11: 06/09/2021 | D11: Surface finish nonconformance | E11: High | F11: Unit replaced under warranty, no trend identified | G11: Closed - CAPA Issued
A12: INC-1094 | B12: RAD-130-3 | C12: 25/01/2021 | D12: Labeling discrepancy | E12: Medium | F12: CAPA opened, in-process inspection added | G12: Closed - Replaced Unit
A13: INC-1095 | B13: RAD-130-3 | C13: 13/04/2025 | D13: Packaging breach | E13: Medium | F13: Root cause traced to packaging vendor, spec updated | G13: Closed - CAPA Issued
A14: INC-1096 | B14: RAD-130-3 | C14: 07/12/2023 | D14: Bent on delivery | E14: Low | F14: No corrective action required, isolated event | G14: Closed - No Action
... A33: INC-1115 | B33: RAD-180-8 | C33: 19/10/2025 | D33: Sterility indicator failure | E33: Medium | F33: Root cause traced to packaging vendor, spec updated | G33: Closed - CAPA Issued

Sheet RIL - Corvid
B1: Corvid Fragment System
A3: Incident ID | B3: Catalog # | C3: Date Reported | D3: Incident Type | E3: Severity | F3: Corrective Action | G3: Status
A4: INC-1116 | B4: CVD-110-1 | C4: 08/07/2023 | D4: Dimensional out of spec | E4: Low | F4: No corrective action required, isolated event | G4: Under Investigation
A5: INC-1117 | B5: CVD-110-1 | C5: 25/08/2023 | D5: Sterility indicator failure | E5: High | F5: No corrective action required, isolated event | G5: Closed - Replaced Unit
A6: INC-1118 | B6: CVD-110-1 | C6: 24/06/2022 | D6: Packaging breach | E6: Low | F6: CAPA opened, in-process inspection added | G6: Closed - Replaced Unit
A7: INC-1119 | B7: CVD-120-2 | C7: 21/01/2025 | D7: Dimensional out of spec | E7: Low | F7: Vendor notified, incoming inspection tightened | G7: Closed - No Action
A8: INC-1120 | B8: CVD-120-2 | C8: 14/03/2021 | D8: Sterility indicator failure | E8: Low | F8: Vendor notified, incoming inspection tightened | G8: Closed - CAPA Issued
A9: INC-1121 | B9: CVD-120-2 | C9: 07/09/2021 | D9: Surface finish nonconformance | E9: Medium | F9: Vendor notified, incoming inspection tightened | G9: Closed - Replaced Unit
A10: INC-1122 | B10: CVD-130-3 | C10: 01/09/2021 | D10: Dimensional out of spec | E10: Medium | F10: Vendor notified, incoming inspection tightened | G10: Closed - No Action
A11: INC-1123 | B11: CVD-130-3 | C11: 24/05/2025 | D11: Dimensional out of spec | E11: Medium | F11: Vendor notified, incoming inspection tightened | G11: Closed - Replaced Unit
A12: INC-1124 | B12: CVD-130-3 | C12: 04/02/2022 | D12: Dimensional out of spec | E12: Low | F12: Unit replaced under warranty, no trend identified | G12: Closed - CAPA Issued
A13: INC-1125 | B13: CVD-130-3 | C13: 17/05/2025 | D13: Labeling discrepancy | E13: Medium | F13: No corrective action required, isolated event | G13: Closed - No Action
A14: INC-1126 | B14: CVD-130-3 | C14: 13/08/2023 | D14: Dimensional out of spec | E14: Low | F14: Unit replaced under warranty, no trend identified | G14: Under Investigation
... A29: INC-1141 | B29: CVD-180-8 | C29: 12/02/2023 | D29: Bent on delivery | E29: Low | F29: Root cause traced to packaging vendor, spec updated | G29: Closed - Replaced Unit

Sheet Maintenance Procedure
B2: Maintenance Procedure
B5: Adding a new Country:
B6: 1. Add the country name to the dropdown list on the Home sheet (data validation source).
B7: 2. Add one row per existing Catalog # to Country Registrations, filled in with that
B8: country's registration class, rule, name, number, and dates.
B9: 3. No changes are needed on Master Catalog, PBS, or any RIL sheet — those are
B10: country-independent.
B12: Adding a new System:
B13: 1. Add the system name to the dropdown list on the Home sheet.
B14: 2. Add its catalog items to Master Catalog, tagging each with the System name and a
B15: sequential 'System Seq' number (1, 2, 3, ...) — the Key column builds itself from those.
B16: 3. Add a column for the new system on PBS and mark which catalog items belong to it.
... B29: dimension is additive rather than requiring a new file.

Sheet Field Mapping
B2: Field Mapping
B3: Add a row here for every label the source text can contain, for every document type.
B4: The parser is generic: it does not know about any document type until you tell it here.
B6: Document Type | C6: Source Label (as it appears in extracted text) | D6: Destination Sheet | E6: Destination Column
B7: Catalog Spec Sheet | C7: Catalog Number | D7: Master Catalog | E7: B
B8: Catalog Spec Sheet | C8: Description | D8: Master Catalog | E8: C
B9: Catalog Spec Sheet | C9: UDI | D9: Master Catalog | E9: D
B10: Catalog Spec Sheet | C10: Drawing Number | D10: Master Catalog | E10: E
B11: Catalog Spec Sheet | C11: Material | D11: Master Catalog | E11: G
B12: Registration Certificate | C12: Catalog Number | D12: Country Registrations | E12: A
B13: Registration Certificate | C13: Country | D13: Country Registrations | E13: B
B14: Registration Certificate | C14: Registration Number | D14: Country Registrations | E14: F
B15: Registration Certificate | C15: Approval Date | D15: Country Registrations | E15: G
B16: Registration Certificate | C16: Expiration Date | D16: Country Registrations | E16: H
B17: Incident Report | C17: Catalog Number | D17: Master RIL | E17: B
... B21: Incident Report | C21: Corrective Action | D21: Master RIL | E21: G

Sheet Paste & Parse
B2: Paste & Parse
B3: Paste text copied out of a PDF or a text-extraction tool below. The macro (see VBA add-on) reads it, splits each 'Label: Value' line, looks the label up in Field Mapping, and stages it for insertion into the right sheet and column.
B5: Document Type: | C5: Catalog Spec Sheet
B7: Paste raw extracted text here (one 'Label: Value' pair per line):
B8: Catalog Number: TRL-110-1 Description: Screw, 2.4mm x 24mm, Trellis family UDI: 00812345678 Drawing Number: DRW-55210-01 Material: Ti 6Al-4V ELI [example — replace with text pasted from your own PDF/extractor output]
B18: Run: Alt+F8 -> ParseAndFill (stages rows below) -> review -> Alt+F8 -> InsertParsedRow (writes them in).
B20: Field | C20: Value | D20: Destination Sheet | E20: Destination Cell | F20: Status
B21: Catalog Number | C21: TRL-110-1 | D21: Master Catalog | E21: B17 | F21: Ready to insert
B22: Description | C22: Screw, 2.4mm x 24mm, Trellis family | D22: Master Catalog | E22: C17 | F22: Ready to insert
B23: UDI | C23: 00812345678 | D23: Master Catalog | E23: D17 | F23: Ready to insert
B24: Drawing Number | C24: DRW-55210-01 | D24: Master Catalog | E24: E17 | F24: Ready to insert
B25: Material | C25: Ti 6Al-4V ELI | D25: Master Catalog | E25: G17 | F25: Ready to insert
B27: (Example of what the preview table looks like after running ParseAndFill in Excel with the VBA add-on loaded — illustrative only; this .xlsx has no macros attached, so the table above is a static example, not live output.)
